<?xml version="1.0"?>
<robot name="hexapod">
  <!-- Colors -->
  <material name="body_color">
    <color rgba="0.3 0.7 0.3 1.0"/>
  </material>
  <material name="head_color">
    <color rgba="0.5 1.0 0.5 1.0"/>
  </material>
  <material name="leg_color">
    <color rgba="0.2 0.4 0.2 1.0"/>
  </material>
  <material name="eye_color">
    <color rgba="1.0 0.5 0.5 1.0"/>
  </material>

  <!-- Robot Body -->
  <link name="body">
    <visual>
      <geometry>
        <box size="1.0 0.4 0.2"/>
      </geometry>
      <material name="body_color"/>
    </visual>
    <collision>
      <geometry>
        <box size="1.0 0.4 0.2"/>
      </geometry>
    </collision>
    <inertial>
      <mass value="1.0"/>
      <inertia ixx="0.01" ixy="0.0" ixz="0.0" iyy="0.05" iyz="0.0" izz="0.05"/>
    </inertial>
  </link>

  <!-- Head -->
  <link name="head">
    <visual>
      <geometry>
        <box size="0.2 0.2 0.1"/>
      </geometry>
      <material name="head_color"/>
    </visual>
    <collision>
      <geometry>
        <box size="0.2 0.2 0.1"/>
      </geometry>
    </collision>
    <inertial>
      <mass value="0.1"/>
      <inertia ixx="0.001" ixy="0.0" ixz="0.0" iyy="0.001" iyz="0.0" izz="0.001"/>
    </inertial>
  </link>

  <joint name="neck_j" type="fixed">
    <parent link="body"/>
    <child link="head"/>
    <origin xyz="0.5 0 0.15" rpy="0 0 0"/>
  </joint>

  <!-- Eyes -->
  <link name="eye_b0">
    <visual>
      <geometry>
        <sphere radius="0.05"/>
      </geometry>
      <material name="eye_color"/>
    </visual>
    <collision>
      <geometry>
        <sphere radius="0.05"/>
      </geometry>
    </collision>
    <inertial>
      <mass value="0.01"/>
      <inertia ixx="0.0001" ixy="0.0" ixz="0.0" iyy="0.0001" iyz="0.0" izz="0.0001"/>
    </inertial>
  </link>

  <joint name="eye_j0" type="fixed">
    <parent link="head"/>
    <child link="eye_b0"/>
    <origin xyz="0.1 0.1 0.05" rpy="0 0 0"/>
  </joint>

  <link name="eye_b1">
    <visual>
      <geometry>
        <sphere radius="0.05"/>
      </geometry>
      <material name="eye_color"/>
    </visual>
    <collision>
      <geometry>
        <sphere radius="0.05"/>
      </geometry>
    </collision>
    <inertial>
      <mass value="0.01"/>
      <inertia ixx="0.0001" ixy="0.0" ixz="0.0" iyy="0.0001" iyz="0.0" izz="0.0001"/>
    </inertial>
  </link>

  <joint name="eye_j1" type="fixed">
    <parent link="head"/>
    <child link="eye_b1"/>
    <origin xyz="0.1 -0.1 0.05" rpy="0 0 0"/>
  </joint>

  <!-- ===================== LEG 0 (Front Left) ===================== -->
  <link name="leg0_body0">
    <visual>
      <geometry>
        <box size="0.1 0.2 0.1"/>
      </geometry>
      <material name="leg_color"/>
    </visual>
    <collision>
      <geometry>
        <box size="0.1 0.2 0.1"/>
      </geometry>
    </collision>
    <inertial>
      <mass value="0.05"/>
      <inertia ixx="0.0001" ixy="0.0" ixz="0.0" iyy="0.0001" iyz="0.0" izz="0.0001"/>
    </inertial>
  </link>

  <joint name="motor_front_leftL_joint" type="fixed">
    <parent link="body"/>
    <child link="leg0_body0"/>
    <origin xyz="0.45 0.2 0" rpy="0 0 0"/>
  </joint>

  <link name="leg0_body1">
    <visual>
      <geometry>
        <box size="0.1 0.2 0.1"/>
      </geometry>
      <material name="leg_color"/>
    </visual>
    <collision>
      <geometry>
        <box size="0.1 0.2 0.1"/>
      </geometry>
    </collision>
    <inertial>
      <mass value="0.05"/>
      <inertia ixx="0.0001" ixy="0.0" ixz="0.0" iyy="0.0001" iyz="0.0" izz="0.0001"/>
    </inertial>
  </link>

  <joint name="motor_front_leftR_joint" type="revolute">
    <parent link="leg0_body0"/>
    <child link="leg0_body1"/>
    <origin xyz="0 0.12 0" rpy="0 0 0"/>
    <axis xyz="0 1 0"/>
    <limit lower="-0.79" upper="0.79" effort="10" velocity="1"/>
    <dynamics damping="0.7"/>
  </joint>

  <link name="leg0_body2">
    <visual>
      <geometry>
        <box size="0.1 0.2 0.1"/>
      </geometry>
      <material name="leg_color"/>
    </visual>
    <collision>
      <geometry>
        <box size="0.1 0.2 0.1"/>
      </geometry>
    </collision>
    <inertial>
      <mass value="0.05"/>
      <inertia ixx="0.0001" ixy="0.0" ixz="0.0" iyy="0.0001" iyz="0.0" izz="0.0001"/>
    </inertial>
  </link>

  <joint name="knee_front_leftL_link" type="revolute">
    <parent link="leg0_body1"/>
    <child link="leg0_body2"/>
    <origin xyz="0 0.12 0" rpy="0 0 0"/>
    <axis xyz="1 0 0"/>
    <limit lower="0" upper="1.05" effort="10" velocity="1"/>
    <dynamics damping="0.7"/>
  </joint>

  <!-- ===================== LEG 1 (Middle Left) ===================== -->
  <link name="leg1_body0">
    <visual>
      <geometry>
        <box size="0.1 0.2 0.1"/>
      </geometry>
      <material name="leg_color"/>
    </visual>
    <collision>
      <geometry>
        <box size="0.1 0.2 0.1"/>
      </geometry>
    </collision>
    <inertial>
      <mass value="0.05"/>
      <inertia ixx="0.0001" ixy="0.0" ixz="0.0" iyy="0.0001" iyz="0.0" izz="0.0001"/>
    </inertial>
  </link>

  <joint name="motor_front_leftL_joint2" type="fixed">
    <parent link="body"/>
    <child link="leg1_body0"/>
    <origin xyz="0 0.2 0" rpy="0 0 0"/>
  </joint>

  <link name="leg1_body1">
    <visual>
      <geometry>
        <box size="0.1 0.2 0.1"/>
      </geometry>
      <material name="leg_color"/>
    </visual>
    <collision>
      <geometry>
        <box size="0.1 0.2 0.1"/>
      </geometry>
    </collision>
    <inertial>
      <mass value="0.05"/>
      <inertia ixx="0.0001" ixy="0.0" ixz="0.0" iyy="0.0001" iyz="0.0" izz="0.0001"/>
    </inertial>
  </link>

  <joint name="motor_front_leftR_joint2" type="revolute">
    <parent link="leg1_body0"/>
    <child link="leg1_body1"/>
    <origin xyz="0 0.12 0" rpy="0 0 0"/>
    <axis xyz="0 1 0"/>
    <limit lower="-0.79" upper="0.79" effort="10" velocity="1"/>
    <dynamics damping="0.7"/>
  </joint>

  <link name="leg1_body2">
    <visual>
      <geometry>
        <box size="0.1 0.2 0.1"/>
      </geometry>
      <material name="leg_color"/>
    </visual>
    <collision>
      <geometry>
        <box size="0.1 0.2 0.1"/>
      </geometry>
    </collision>
    <inertial>
      <mass value="0.05"/>
      <inertia ixx="0.0001" ixy="0.0" ixz="0.0" iyy="0.0001" iyz="0.0" izz="0.0001"/>
    </inertial>
  </link>

  <joint name="knee_front_leftR_link" type="revolute">
    <parent link="leg1_body1"/>
    <child link="leg1_body2"/>
    <origin xyz="0 0.12 0" rpy="0 0 0"/>
    <axis xyz="1 0 0"/>
    <limit lower="0" upper="1.05" effort="10" velocity="1"/>
    <dynamics damping="0.7"/>
  </joint>

  <!-- ===================== LEG 2 (Back Left) ===================== -->
  <link name="leg2_body0">
    <visual>
      <geometry>
        <box size="0.1 0.2 0.1"/>
      </geometry>
      <material name="leg_color"/>
    </visual>
    <collision>
      <geometry>
        <box size="0.1 0.2 0.1"/>
      </geometry>
    </collision>
    <inertial>
      <mass value="0.05"/>
      <inertia ixx="0.0001" ixy="0.0" ixz="0.0" iyy="0.0001" iyz="0.0" izz="0.0001"/>
    </inertial>
  </link>

  <joint name="motor_back_leftL_joint" type="fixed">
    <parent link="body"/>
    <child link="leg2_body0"/>
    <origin xyz="-0.45 0.2 0" rpy="0 0 0"/>
  </joint>

  <link name="leg2_body1">
    <visual>
      <geometry>
        <box size="0.1 0.2 0.1"/>
      </geometry>
      <material name="leg_color"/>
    </visual>
    <collision>
      <geometry>
        <box size="0.1 0.2 0.1"/>
      </geometry>
    </collision>
    <inertial>
      <mass value="0.05"/>
      <inertia ixx="0.0001" ixy="0.0" ixz="0.0" iyy="0.0001" iyz="0.0" izz="0.0001"/>
    </inertial>
  </link>

  <joint name="motor_back_leftR_joint" type="revolute">
    <parent link="leg2_body0"/>
    <child link="leg2_body1"/>
    <origin xyz="0 0.12 0" rpy="0 0 0"/>
    <axis xyz="0 1 0"/>
    <limit lower="-0.79" upper="0.79" effort="10" velocity="1"/>
    <dynamics damping="0.7"/>
  </joint>

  <link name="leg2_body2">
    <visual>
      <geometry>
        <box size="0.1 0.2 0.1"/>
      </geometry>
      <material name="leg_color"/>
    </visual>
    <collision>
      <geometry>
        <box size="0.1 0.2 0.1"/>
      </geometry>
    </collision>
    <inertial>
      <mass value="0.05"/>
      <inertia ixx="0.0001" ixy="0.0" ixz="0.0" iyy="0.0001" iyz="0.0" izz="0.0001"/>
    </inertial>
  </link>

  <joint name="knee_back_leftL_link" type="revolute">
    <parent link="leg2_body1"/>
    <child link="leg2_body2"/>
    <origin xyz="0 0.12 0" rpy="0 0 0"/>
    <axis xyz="1 0 0"/>
    <limit lower="0" upper="1.05" effort="10" velocity="1"/>
    <dynamics damping="0.7"/>
  </joint>

  <!-- ===================== LEG 3 (Front Right) ===================== -->
  <link name="leg3_body0">
    <visual>
      <geometry>
        <box size="0.1 0.2 0.1"/>
      </geometry>
      <material name="leg_color"/>
    </visual>
    <collision>
      <geometry>
        <box size="0.1 0.2 0.1"/>
      </geometry>
    </collision>
    <inertial>
      <mass value="0.05"/>
      <inertia ixx="0.0001" ixy="0.0" ixz="0.0" iyy="0.0001" iyz="0.0" izz="0.0001"/>
    </inertial>
  </link>

  <joint name="motor_front_rightL_joint" type="fixed">
    <parent link="body"/>
    <child link="leg3_body0"/>
    <origin xyz="0.45 -0.2 0" rpy="0 0 3.14159"/>
  </joint>

  <link name="leg3_body1">
    <visual>
      <geometry>
        <box size="0.1 0.2 0.1"/>
      </geometry>
      <material name="leg_color"/>
    </visual>
    <collision>
      <geometry>
        <box size="0.1 0.2 0.1"/>
      </geometry>
    </collision>
    <inertial>
      <mass value="0.05"/>
      <inertia ixx="0.0001" ixy="0.0" ixz="0.0" iyy="0.0001" iyz="0.0" izz="0.0001"/>
    </inertial>
  </link>

  <joint name="motor_front_rightR_joint" type="revolute">
    <parent link="leg3_body0"/>
    <child link="leg3_body1"/>
    <origin xyz="0 0.12 0" rpy="0 0 0"/>
    <axis xyz="0 1 0"/>
    <limit lower="-0.79" upper="0.79" effort="10" velocity="1"/>
    <dynamics damping="0.7"/>
  </joint>

  <link name="leg3_body2">
    <visual>
      <geometry>
        <box size="0.1 0.2 0.1"/>
      </geometry>
      <material name="leg_color"/>
    </visual>
    <collision>
      <geometry>
        <box size="0.1 0.2 0.1"/>
      </geometry>
    </collision>
    <inertial>
      <mass value="0.05"/>
      <inertia ixx="0.0001" ixy="0.0" ixz="0.0" iyy="0.0001" iyz="0.0" izz="0.0001"/>
    </inertial>
  </link>

  <joint name="knee_front_rightL_link" type="revolute">
    <parent link="leg3_body1"/>
    <child link="leg3_body2"/>
    <origin xyz="0 0.12 0" rpy="0 0 0"/>
    <axis xyz="1 0 0"/>
    <limit lower="0" upper="1.05" effort="10" velocity="1"/>
    <dynamics damping="0.7"/>
  </joint>

  <!-- ===================== LEG 4 (Middle Right) ===================== -->
  <link name="leg4_body0">
    <visual>
      <geometry>
        <box size="0.1 0.2 0.1"/>
      </geometry>
      <material name="leg_color"/>
    </visual>
    <collision>
      <geometry>
        <box size="0.1 0.2 0.1"/>
      </geometry>
    </collision>
    <inertial>
      <mass value="0.05"/>
      <inertia ixx="0.0001" ixy="0.0" ixz="0.0" iyy="0.0001" iyz="0.0" izz="0.0001"/>
    </inertial>
  </link>

  <joint name="motor_back_rightL_joint2" type="fixed">
    <parent link="body"/>
    <child link="leg4_body0"/>
    <origin xyz="0 -0.2 0" rpy="0 0 3.14159"/>
  </joint>

  <link name="leg4_body1">
    <visual>
      <geometry>
        <box size="0.1 0.2 0.1"/>
      </geometry>
      <material name="leg_color"/>
    </visual>
    <collision>
      <geometry>
        <box size="0.1 0.2 0.1"/>
      </geometry>
    </collision>
    <inertial>
      <mass value="0.05"/>
      <inertia ixx="0.0001" ixy="0.0" ixz="0.0" iyy="0.0001" iyz="0.0" izz="0.0001"/>
    </inertial>
  </link>

  <joint name="motor_back_rightR_joint2" type="revolute">
    <parent link="leg4_body0"/>
    <child link="leg4_body1"/>
    <origin xyz="0 0.12 0" rpy="0 0 0"/>
    <axis xyz="0 1 0"/>
    <limit lower="-0.79" upper="0.79" effort="10" velocity="1"/>
    <dynamics damping="0.7"/>
  </joint>

  <link name="leg4_body2">
    <visual>
      <geometry>
        <box size="0.1 0.2 0.1"/>
      </geometry>
      <material name="leg_color"/>
    </visual>
    <collision>
      <geometry>
        <box size="0.1 0.2 0.1"/>
      </geometry>
    </collision>
    <inertial>
      <mass value="0.05"/>
      <inertia ixx="0.0001" ixy="0.0" ixz="0.0" iyy="0.0001" iyz="0.0" izz="0.0001"/>
    </inertial>
  </link>

  <joint name="knee_front_rightR_link" type="revolute">
    <parent link="leg4_body1"/>
    <child link="leg4_body2"/>
    <origin xyz="0 0.12 0" rpy="0 0 0"/>
    <axis xyz="1 0 0"/>
    <limit lower="0" upper="1.05" effort="10" velocity="1"/>
    <dynamics damping="0.7"/>
  </joint>

  <!-- ===================== LEG 5 (Back Right) ===================== -->
  <link name="leg5_body0">
    <visual>
      <geometry>
        <box size="0.1 0.2 0.1"/>
      </geometry>
      <material name="leg_color"/>
    </visual>
    <collision>
      <geometry>
        <box size="0.1 0.2 0.1"/>
      </geometry>
    </collision>
    <inertial>
      <mass value="0.05"/>
      <inertia ixx="0.0001" ixy="0.0" ixz="0.0" iyy="0.0001" iyz="0.0" izz="0.0001"/>
    </inertial>
  </link>

  <joint name="motor_back_rightL_joint" type="fixed">
    <parent link="body"/>
    <child link="leg5_body0"/>
    <origin xyz="-0.45 -0.2 0" rpy="0 0 3.14159"/>
  </joint>

  <link name="leg5_body1">
    <visual>
      <geometry>
        <box size="0.1 0.2 0.1"/>
      </geometry>
      <material name="leg_color"/>
    </visual>
    <collision>
      <geometry>
        <box size="0.1 0.2 0.1"/>
      </geometry>
    </collision>
    <inertial>
      <mass value="0.05"/>
      <inertia ixx="0.0001" ixy="0.0" ixz="0.0" iyy="0.0001" iyz="0.0" izz="0.0001"/>
    </inertial>
  </link>

  <joint name="motor_back_rightR_joint" type="revolute">
    <parent link="leg5_body0"/>
    <child link="leg5_body1"/>
    <origin xyz="0 0.12 0" rpy="0 0 0"/>
    <axis xyz="0 1 0"/>
    <limit lower="-0.79" upper="0.79" effort="10" velocity="1"/>
    <dynamics damping="0.7"/>
  </joint>

  <link name="leg5_body2">
    <visual>
      <geometry>
        <box size="0.1 0.2 0.1"/>
      </geometry>
      <material name="leg_color"/>
    </visual>
    <collision>
      <geometry>
        <box size="0.1 0.2 0.1"/>
      </geometry>
    </collision>
    <inertial>
      <mass value="0.05"/>
      <inertia ixx="0.0001" ixy="0.0" ixz="0.0" iyy="0.0001" iyz="0.0" izz="0.0001"/>
    </inertial>
  </link>

  <joint name="knee_back_rightR_link" type="revolute">
    <parent link="leg5_body1"/>
    <child link="leg5_body2"/>
    <origin xyz="0 0.12 0" rpy="0 0 0"/>
    <axis xyz="1 0 0"/>
    <limit lower="0" upper="1.05" effort="10" velocity="1"/>
    <dynamics damping="0.7"/>
  </joint>

</robot>