<?xml version="1.0"?>
<robot name="hexapod">
  <!-- Robot body dimensions from C++ code -->
  <material name="green">
    <color rgba="0.3 0.7 0.3 1.0"/>
  </material>
  
  <material name="light_green">
    <color rgba="0.5 1.0 0.5 1.0"/>
  </material>
  
  <material name="dark_green">
    <color rgba="0.2 0.4 0.2 1.0"/>
  </material>
  
  <material name="red">
    <color rgba="1.0 0.5 0.5 1.0"/>
  </material>
  
  <material name="purple">
    <color rgba="1.0 0.0 1.0 1.0"/>
  </material>

  <!-- Main body -->
  <link name="base_link">
    <visual>
      <geometry>
        <box size="1.0 0.4 0.2"/>
      </geometry>
      <material name="green"/>
    </visual>
    <collision>
      <geometry>
        <box size="1.0 0.4 0.2"/>
      </geometry>
    </collision>
    <inertial>
      <mass value="1.0"/>
      <inertia ixx="0.01" ixy="0" ixz="0" iyy="0.01" iyz="0" izz="0.01"/>
    </inertial>
  </link>

  <!-- Head -->
  <link name="head">
    <visual>
      <geometry>
        <box size="0.2 0.2 0.1"/>
      </geometry>
      <material name="light_green"/>
    </visual>
    <collision>
      <geometry>
        <box size="0.2 0.2 0.1"/>
      </geometry>
    </collision>
    <inertial>
      <mass value="0.1"/>
      <inertia ixx="0.001" ixy="0" ixz="0" iyy="0.001" iyz="0" izz="0.001"/>
    </inertial>
  </link>

  <joint name="neck_joint" type="fixed">
    <parent link="base_link"/>
    <child link="head"/>
    <origin xyz="0.5 0 0.15" rpy="0 0 0"/>
  </joint>

  <!-- Eyes -->
  <link name="left_eye">
    <visual>
      <geometry>
        <sphere radius="0.05"/>
      </geometry>
      <material name="red"/>
    </visual>
    <collision>
      <geometry>
        <sphere radius="0.05"/>
      </geometry>
    </collision>
    <inertial>
      <mass value="0.01"/>
      <inertia ixx="0.0001" ixy="0" ixz="0" iyy="0.0001" iyz="0" izz="0.0001"/>
    </inertial>
  </link>

  <joint name="left_eye_joint" type="fixed">
    <parent link="head"/>
    <child link="left_eye"/>
    <origin xyz="0.1 0.1 0.05" rpy="0 0 0"/>
  </joint>

  <link name="right_eye">
    <visual>
      <geometry>
        <sphere radius="0.05"/>
      </geometry>
      <material name="red"/>
    </visual>
    <collision>
      <geometry>
        <sphere radius="0.05"/>
      </geometry>
    </collision>
    <inertial>
      <mass value="0.01"/>
      <inertia ixx="0.0001" ixy="0" ixz="0" iyy="0.0001" iyz="0" izz="0.0001"/>
    </inertial>
  </link>

  <joint name="right_eye_joint" type="fixed">
    <parent link="head"/>
    <child link="right_eye"/>
    <origin xyz="0.1 -0.1 0.05" rpy="0 0 0"/>
  </joint>

  <!-- Legs - Creating 6 legs with 3 segments each -->
  <!-- Leg positions from C++ code: 
       [px, py, pz], [0, py, pz], [-px, py, pz], 
       [px, -py, pz], [0, -py, pz], [-px, -py, pz] -->

  <!-- Leg 0: Front-Right -->
  <link name="leg0_segment0">
    <visual>
      <geometry>
        <box size="0.1 0.2 0.1"/>
      </geometry>
      <material name="dark_green"/>
    </visual>
    <collision>
      <geometry>
        <box size="0.1 0.2 0.1"/>
      </geometry>
    </collision>
    <inertial>
      <mass value="0.05"/>
      <inertia ixx="0.0001" ixy="0" ixz="0" iyy="0.0001" iyz="0" izz="0.0001"/>
    </inertial>
  </link>

  <joint name="leg0_joint0" type="fixed">
    <parent link="base_link"/>
    <child link="leg0_segment0"/>
    <origin xyz="0.45 0.2 0.1" rpy="0 0 0"/>
  </joint>

  <link name="leg0_segment1">
    <visual>
      <geometry>
        <box size="0.1 0.2 0.1"/>
      </geometry>
      <material name="dark_green"/>
    </visual>
    <collision>
      <geometry>
        <box size="0.1 0.2 0.1"/>
      </geometry>
    </collision>
    <inertial>
      <mass value="0.05"/>
      <inertia ixx="0.0001" ixy="0" ixz="0" iyy="0.0001" iyz="0" izz="0.0001"/>
    </inertial>
  </link>

  <joint name="leg0_joint1" type="revolute">
    <parent link="leg0_segment0"/>
    <child link="leg0_segment1"/>
    <origin xyz="0 0.12 0" rpy="0 0 0"/>
    <axis xyz="0 1 0"/>
    <limit lower="-0.785" upper="0.785" effort="10" velocity="1"/>
    <dynamics damping="0.7"/>
  </joint>

  <link name="leg0_segment2">
    <visual>
      <geometry>
        <box size="0.1 0.2 0.1"/>
      </geometry>
      <material name="dark_green"/>
    </visual>
    <collision>
      <geometry>
        <box size="0.1 0.2 0.1"/>
      </geometry>
    </collision>
    <inertial>
      <mass value="0.05"/>
      <inertia ixx="0.0001" ixy="0" ixz="0" iyy="0.0001" iyz="0" izz="0.0001"/>
    </inertial>
  </link>

  <joint name="leg0_joint2" type="revolute">
    <parent link="leg0_segment1"/>
    <child link="leg0_segment2"/>
    <origin xyz="0 0.12 0" rpy="0 0 0"/>
    <axis xyz="1 0 0"/>
    <limit lower="0" upper="1.047" effort="10" velocity="1"/>
    <dynamics damping="0.7"/>
  </joint>

  <link name="leg0_segment3">
    <visual>
      <geometry>
        <box size="0.1 0.2 0.1"/>
      </geometry>
      <material name="dark_green"/>
    </visual>
    <collision>
      <geometry>
        <box size="0.1 0.2 0.1"/>
      </geometry>
    </collision>
    <inertial>
      <mass value="0.05"/>
      <inertia ixx="0.0001" ixy="0" ixz="0" iyy="0.0001" iyz="0" izz="0.0001"/>
    </inertial>
  </link>

  <joint name="leg0_joint3" type="revolute">
    <parent link="leg0_segment2"/>
    <child link="leg0_segment3"/>
    <origin xyz="0 0.12 0" rpy="0 0 0"/>
    <axis xyz="1 0 0"/>
    <limit lower="0" upper="1.047" effort="10" velocity="1"/>
    <dynamics damping="0.7"/>
  </joint>

  <!-- Leg 1: Front-Middle -->
  <link name="leg1_segment0">
    <visual>
      <geometry>
        <box size="0.1 0.2 0.1"/>
      </geometry>
      <material name="dark_green"/>
    </visual>
    <collision>
      <geometry>
        <box size="0.1 0.2 0.1"/>
      </geometry>
    </collision>
    <inertial>
      <mass value="0.05"/>
      <inertia ixx="0.0001" ixy="0" ixz="0" iyy="0.0001" iyz="0" izz="0.0001"/>
    </inertial>
  </link>

  <joint name="leg1_joint0" type="fixed">
    <parent link="base_link"/>
    <child link="leg1_segment0"/>
    <origin xyz="0 0.2 0.1" rpy="0 0 0"/>
  </joint>

  <link name="leg1_segment1">
    <visual>
      <geometry>
        <box size="0.1 0.2 0.1"/>
      </geometry>
      <material name="dark_green"/>
    </visual>
    <collision>
      <geometry>
        <box size="0.1 0.2 0.1"/>
      </geometry>
    </collision>
    <inertial>
      <mass value="0.05"/>
      <inertia ixx="0.0001" ixy="0" ixz="0" iyy="0.0001" iyz="0" izz="0.0001"/>
    </inertial>
  </link>

  <joint name="leg1_joint1" type="revolute">
    <parent link="leg1_segment0"/>
    <child link="leg1_segment1"/>
    <origin xyz="0 0.12 0" rpy="0 0 0"/>
    <axis xyz="0 1 0"/>
    <limit lower="-0.785" upper="0.785" effort="10" velocity="1"/>
    <dynamics damping="0.7"/>
  </joint>

  <link name="leg1_segment2">
    <visual>
      <geometry>
        <box size="0.1 0.2 0.1"/>
      </geometry>
      <material name="dark_green"/>
    </visual>
    <collision>
      <geometry>
        <box size="0.1 0.2 0.1"/>
      </geometry>
    </collision>
    <inertial>
      <mass value="0.05"/>
      <inertia ixx="0.0001" ixy="0" ixz="0" iyy="0.0001" iyz="0" izz="0.0001"/>
    </inertial>
  </link>

  <joint name="leg1_joint2" type="revolute">
    <parent link="leg1_segment1"/>
    <child link="leg1_segment2"/>
    <origin xyz="0 0.12 0" rpy="0 0 0"/>
    <axis xyz="1 0 0"/>
    <limit lower="0" upper="1.047" effort="10" velocity="1"/>
    <dynamics damping="0.7"/>
  </joint>

  <link name="leg1_segment3">
    <visual>
      <geometry>
        <box size="0.1 0.2 0.1"/>
      </geometry>
      <material name="dark_green"/>
    </visual>
    <collision>
      <geometry>
        <box size="0.1 0.2 0.1"/>
      </geometry>
    </collision>
    <inertial>
      <mass value="0.05"/>
      <inertia ixx="0.0001" ixy="0" ixz="0" iyy="0.0001" iyz="0" izz="0.0001"/>
    </inertial>
  </link>

  <joint name="leg1_joint3" type="revolute">
    <parent link="leg1_segment2"/>
    <child link="leg1_segment3"/>
    <origin xyz="0 0.12 0" rpy="0 0 0"/>
    <axis xyz="1 0 0"/>
    <limit lower="0" upper="1.047" effort="10" velocity="1"/>
    <dynamics damping="0.7"/>
  </joint>

  <!-- Remaining legs follow the same pattern -->
  <!-- Leg 2: Front-Left -->
  <link name="leg2_segment0">
    <visual>
      <geometry>
        <box size="0.1 0.2 0.1"/>
      </geometry>
      <material name="dark_green"/>
    </visual>
    <collision>
      <geometry>
        <box size="0.1 0.2 0.1"/>
      </geometry>
    </collision>
    <inertial>
      <mass value="0.05"/>
      <inertia ixx="0.0001" ixy="0" ixz="0" iyy="0.0001" iyz="0" izz="0.0001"/>
    </inertial>
  </link>

  <joint name="leg2_joint0" type="fixed">
    <parent link="base_link"/>
    <child link="leg2_segment0"/>
    <origin xyz="-0.45 0.2 0.1" rpy="0 0 0"/>
  </joint>

  <link name="leg2_segment1">
    <visual>
      <geometry>
        <box size="0.1 0.2 0.1"/>
      </geometry>
      <material name="dark_green"/>
    </visual>
    <collision>
      <geometry>
        <box size="0.1 0.2 0.1"/>
      </geometry>
    </collision>
    <inertial>
      <mass value="0.05"/>
      <inertia ixx="0.0001" ixy="0" ixz="0" iyy="0.0001" iyz="0" izz="0.0001"/>
    </inertial>
  </link>

  <joint name="leg2_joint1" type="revolute">
    <parent link="leg2_segment0"/>
    <child link="leg2_segment1"/>
    <origin xyz="0 0.12 0" rpy="0 0 0"/>
    <axis xyz="0 1 0"/>
    <limit lower="-0.785" upper="0.785" effort="10" velocity="1"/>
    <dynamics damping="0.7"/>
  </joint>

  <!-- Add equivalent segments and joints for legs 3-5 -->
  <!-- Leg 3: Back-Right -->
  <link name="leg3_segment0">
    <visual>
      <geometry>
        <box size="0.1 0.2 0.1"/>
      </geometry>
      <material name="dark_green"/>
    </visual>
    <collision>
      <geometry>
        <box size="0.1 0.2 0.1"/>
      </geometry>
    </collision>
    <inertial>
      <mass value="0.05"/>
      <inertia ixx="0.0001" ixy="0" ixz="0" iyy="0.0001" iyz="0" izz="0.0001"/>
    </inertial>
  </link>

  <joint name="leg3_joint0" type="fixed">
    <parent link="base_link"/>
    <child link="leg3_segment0"/>
    <origin xyz="0.45 -0.2 0.1" rpy="0 0 3.14159"/>
  </joint>

  <link name="leg3_segment1">
    <visual>
      <geometry>
        <box size="0.1 0.2 0.1"/>
      </geometry>
      <material name="dark_green"/>
    </visual>
    <collision>
      <geometry>
        <box size="0.1 0.2 0.1"/>
      </geometry>
    </collision>
    <inertial>
      <mass value="0.05"/>
      <inertia ixx="0.0001" ixy="0" ixz="0" iyy="0.0001" iyz="0" izz="0.0001"/>
    </inertial>
  </link>

  <joint name="leg3_joint1" type="revolute">
    <parent link="leg3_segment0"/>
    <child link="leg3_segment1"/>
    <origin xyz="0 0.12 0" rpy="0 0 0"/>
    <axis xyz="0 1 0"/>
    <limit lower="-0.785" upper="0.785" effort="10" velocity="1"/>
    <dynamics damping="0.7"/>
  </joint>

  <!-- Leg 4: Back-Middle -->
  <link name="leg4_segment0">
    <visual>
      <geometry>
        <box size="0.1 0.2 0.1"/>
      </geometry>
      <material name="dark_green"/>
    </visual>
    <collision>
      <geometry>
        <box size="0.1 0.2 0.1"/>
      </geometry>
    </collision>
    <inertial>
      <mass value="0.05"/>
      <inertia ixx="0.0001" ixy="0" ixz="0" iyy="0.0001" iyz="0" izz="0.0001"/>
    </inertial>
  </link>

  <joint name="leg4_joint0" type="fixed">
    <parent link="base_link"/>
    <child link="leg4_segment0"/>
    <origin xyz="0 -0.2 0.1" rpy="0 0 3.14159"/>
  </joint>

  <!-- Leg 5: Back-Left -->
  <link name="leg5_segment0">
    <visual>
      <geometry>
        <box size="0.1 0.2 0.1"/>
      </geometry>
      <material name="dark_green"/>
    </visual>
    <collision>
      <geometry>
        <box size="0.1 0.2 0.1"/>
      </geometry>
    </collision>
    <inertial>
      <mass value="0.05"/>
      <inertia ixx="0.0001" ixy="0" ixz="0" iyy="0.0001" iyz="0" izz="0.0001"/>
    </inertial>
  </link>

  <joint name="leg5_joint0" type="fixed">
    <parent link="base_link"/>
    <child link="leg5_segment0"/>
    <origin xyz="-0.45 -0.2 0.1" rpy="0 0 3.14159"/>
  </joint>

  <!-- Add equivalent segments and joints for remaining legs -->
  <!-- Note: This is a simplified version. For a complete URDF, 
       replicate the pattern for all segments of all 6 legs -->
</robot>