<?xml version="1.0"?>
<robot name="hexapod">
  <!-- Colors -->
  <material name="body_color">
    <color rgba="0.3 0.7 0.3 1.0"/>
  </material>
  <material name="head_color">
    <color rgba="0.5 1.0 0.5 1.0"/>
  </material>
  <material name="leg_color">
    <color rgba="0.2 0.4 0.2 1.0"/>
  </material>
  <material name="eye_color">
    <color rgba="1.0 0.5 0.5 1.0"/>
  </material>

  <!-- Robot Body -->
  <link name="body">
    <visual>
      <geometry>
        <box size="1.0 0.4 0.2"/>
      </geometry>
      <material name="body_color"/>
    </visual>
    <collision>
      <geometry>
        <box size="1.0 0.4 0.2"/>
      </geometry>
    </collision>
    <inertial>
      <mass value="1.0"/>
      <inertia ixx="0.01" ixy="0.0" ixz="0.0" iyy="0.05" iyz="0.0" izz="0.05"/>
    </inertial>
  </link>

  <!-- Head -->
  <link name="head">
    <visual>
      <geometry>
        <box size="0.2 0.2 0.1"/>
      </geometry>
      <material name="head_color"/>
    </visual>
    <collision>
      <geometry>
        <box size="0.2 0.2 0.1"/>
      </geometry>
    </collision>
    <inertial>
      <mass value="0.1"/>
      <inertia ixx="0.001" ixy="0.0" ixz="0.0" iyy="0.001" iyz="0.0" izz="0.001"/>
    </inertial>
  </link>

  <joint name="neck_j" type="fixed">
    <parent link="body"/>
    <child link="head"/>
    <origin xyz="0.5 0 0.15" rpy="0 0 0"/>
  </joint>

  <!-- Eyes -->
  <link name="eye_b0">
    <visual>
      <geometry>
        <sphere radius="0.05"/>
      </geometry>
      <material name="eye_color"/>
    </visual>
    <collision>
      <geometry>
        <sphere radius="0.05"/>
      </geometry>
    </collision>
    <inertial>
      <mass value="0.01"/>
      <inertia ixx="0.0001" ixy="0.0" ixz="0.0" iyy="0.0001" iyz="0.0" izz="0.0001"/>
    </inertial>
  </link>

  <joint name="eye_j0" type="fixed">
    <parent link="head"/>
    <child link="eye_b0"/>
    <origin xyz="0.1 0.1 0.05" rpy="0 0 0"/>
  </joint>

  <link name="eye_b1">
    <visual>
      <geometry>
        <sphere radius="0.05"/>
      </geometry>
      <material name="eye_color"/>
    </visual>
    <collision>
      <geometry>
        <sphere radius="0.05"/>
      </geometry>
    </collision>
    <inertial>
      <mass value="0.01"/>
      <inertia ixx="0.0001" ixy="0.0" ixz="0.0" iyy="0.0001" iyz="0.0" izz="0.0001"/>
    </inertial>
  </link>

  <joint name="eye_j1" type="fixed">
    <parent link="head"/>
    <child link="eye_b1"/>
    <origin xyz="0.1 -0.1 0.05" rpy="0 0 0"/>
  </joint>

  <!-- Legs -->
  <!-- Front Left Leg (leg 0) -->
  <link name="leg_0_body0">
    <visual>
      <geometry>
        <box size="0.1 0.2 0.1"/>
      </geometry>
      <material name="leg_color"/>
    </visual>
    <collision>
      <geometry>
        <box size="0.1 0.2 0.1"/>
      </geometry>
    </collision>
    <inertial>
      <mass value="0.05"/>
      <inertia ixx="0.0001" ixy="0.0" ixz="0.0" iyy="0.0001" iyz="0.0" izz="0.0001"/>
    </inertial>
  </link>

  <joint name="leg_0_joint0" type="fixed">
    <parent link="body"/>
    <child link="leg_0_body0"/>
    <origin xyz="0.45 0.2 -0.1" rpy="0 0 0"/>
  </joint>

  <link name="leg_0_body1">
    <visual>
      <geometry>
        <box size="0.1 0.2 0.1"/>
      </geometry>
      <material name="leg_color"/>
    </visual>
    <collision>
      <geometry>
        <box size="0.1 0.2 0.1"/>
      </geometry>
    </collision>
    <inertial>
      <mass value="0.05"/>
      <inertia ixx="0.0001" ixy="0.0" ixz="0.0" iyy="0.0001" iyz="0.0" izz="0.0001"/>
    </inertial>
  </link>

  <joint name="leg_0_joint1" type="revolute">
    <parent link="leg_0_body0"/>
    <child link="leg_0_body1"/>
    <origin xyz="0 0.12 0" rpy="0 0 0"/>
    <axis xyz="0 1 0"/>
    <limit lower="-0.79" upper="0.79" effort="10" velocity="1"/>
    <dynamics damping="0.7"/>
  </joint>

  <link name="leg_0_body2">
    <visual>
      <geometry>
        <box size="0.1 0.2 0.1"/>
      </geometry>
      <material name="leg_color"/>
    </visual>
    <collision>
      <geometry>
        <box size="0.1 0.2 0.1"/>
      </geometry>
    </collision>
    <inertial>
      <mass value="0.05"/>
      <inertia ixx="0.0001" ixy="0.0" ixz="0.0" iyy="0.0001" iyz="0.0" izz="0.0001"/>
    </inertial>
  </link>

  <joint name="leg_0_joint2" type="revolute">
    <parent link="leg_0_body1"/>
    <child link="leg_0_body2"/>
    <origin xyz="0 0.12 0" rpy="0 0 0"/>
    <axis xyz="1 0 0"/>
    <limit lower="0" upper="1.05" effort="10" velocity="1"/>
    <dynamics damping="0.7"/>
  </joint>

  <link name="leg_0_body3">
    <visual>
      <geometry>
        <box size="0.1 0.2 0.1"/>
      </geometry>
      <material name="leg_color"/>
    </visual>
    <collision>
      <geometry>
        <box size="0.1 0.2 0.1"/>
      </geometry>
    </collision>
    <inertial>
      <mass value="0.05"/>
      <inertia ixx="0.0001" ixy="0.0" ixz="0.0" iyy="0.0001" iyz="0.0" izz="0.0001"/>
    </inertial>
  </link>

  <joint name="leg_0_joint3" type="revolute">
    <parent link="leg_0_body2"/>
    <child link="leg_0_body3"/>
    <origin xyz="0 0.12 0" rpy="0 0 0"/>
    <axis xyz="1 0 0"/>
    <limit lower="0" upper="1.05" effort="10" velocity="1"/>
    <dynamics damping="0.7"/>
  </joint>

  <!-- Middle Left Leg (leg 1) -->
  <link name="leg_1_body0">
    <visual>
      <geometry>
        <box size="0.1 0.2 0.1"/>
      </geometry>
      <material name="leg_color"/>
    </visual>
    <collision>
      <geometry>
        <box size="0.1 0.2 0.1"/>
      </geometry>
    </collision>
    <inertial>
      <mass value="0.05"/>
      <inertia ixx="0.0001" ixy="0.0" ixz="0.0" iyy="0.0001" iyz="0.0" izz="0.0001"/>
    </inertial>
  </link>

  <joint name="leg_1_joint0" type="fixed">
    <parent link="body"/>
    <child link="leg_1_body0"/>
    <origin xyz="0 0.2 -0.1" rpy="0 0 0"/>
  </joint>

  <link name="leg_1_body1">
    <visual>
      <geometry>
        <box size="0.1 0.2 0.1"/>
      </geometry>
      <material name="leg_color"/>
    </visual>
    <collision>
      <geometry>
        <box size="0.1 0.2 0.1"/>
      </geometry>
    </collision>
    <inertial>
      <mass value="0.05"/>
      <inertia ixx="0.0001" ixy="0.0" ixz="0.0" iyy="0.0001" iyz="0.0" izz="0.0001"/>
    </inertial>
  </link>

  <joint name="leg_1_joint1" type="revolute">
    <parent link="leg_1_body0"/>
    <child link="leg_1_body1"/>
    <origin xyz="0 0.12 0" rpy="0 0 0"/>
    <axis xyz="0 1 0"/>
    <limit lower="-0.79" upper="0.79" effort="10" velocity="1"/>
    <dynamics damping="0.7"/>
  </joint>

  <link name="leg_1_body2">
    <visual>
      <geometry>
        <box size="0.1 0.2 0.1"/>
      </geometry>
      <material name="leg_color"/>
    </visual>
    <collision>
      <geometry>
        <box size="0.1 0.2 0.1"/>
      </geometry>
    </collision>
    <inertial>
      <mass value="0.05"/>
      <inertia ixx="0.0001" ixy="0.0" ixz="0.0" iyy="0.0001" iyz="0.0" izz="0.0001"/>
    </inertial>
  </link>

  <joint name="leg_1_joint2" type="revolute">
    <parent link="leg_1_body1"/>
    <child link="leg_1_body2"/>
    <origin xyz="0 0.12 0" rpy="0 0 0"/>
    <axis xyz="1 0 0"/>
    <limit lower="0" upper="1.05" effort="10" velocity="1"/>
    <dynamics damping="0.7"/>
  </joint>

  <link name="leg_1_body3">
    <visual>
      <geometry>
        <box size="0.1 0.2 0.1"/>
      </geometry>
      <material name="leg_color"/>
    </visual>
    <collision>
      <geometry>
        <box size="0.1 0.2 0.1"/>
      </geometry>
    </collision>
    <inertial>
      <mass value="0.05"/>
      <inertia ixx="0.0001" ixy="0.0" ixz="0.0" iyy="0.0001" iyz="0.0" izz="0.0001"/>
    </inertial>
  </link>

  <joint name="leg_1_joint3" type="revolute">
    <parent link="leg_1_body2"/>
    <child link="leg_1_body3"/>
    <origin xyz="0 0.12 0" rpy="0 0 0"/>
    <axis xyz="1 0 0"/>
    <limit lower="0" upper="1.05" effort="10" velocity="1"/>
    <dynamics damping="0.7"/>
  </joint>

  <!-- Rear Left Leg (leg 2) -->
  <link name="leg_2_body0">
    <visual>
      <geometry>
        <box size="0.1 0.2 0.1"/>
      </geometry>
      <material name="leg_color"/>
    </visual>
    <collision>
      <geometry>
        <box size="0.1 0.2 0.1"/>
      </geometry>
    </collision>
    <inertial>
      <mass value="0.05"/>
      <inertia ixx="0.0001" ixy="0.0" ixz="0.0" iyy="0.0001" iyz="0.0" izz="0.0001"/>
    </inertial>
  </link>

  <joint name="leg_2_joint0" type="fixed">
    <parent link="body"/>
    <child link="leg_2_body0"/>
    <origin xyz="-0.45 0.2 -0.1" rpy="0 0 0"/>
  </joint>

  <link name="leg_2_body1">
    <visual>
      <geometry>
        <box size="0.1 0.2 0.1"/>
      </geometry>
      <material name="leg_color"/>
    </visual>
    <collision>
      <geometry>
        <box size="0.1 0.2 0.1"/>
      </geometry>
    </collision>
    <inertial>
      <mass value="0.05"/>
      <inertia ixx="0.0001" ixy="0.0" ixz="0.0" iyy="0.0001" iyz="0.0" izz="0.0001"/>
    </inertial>
  </link>

  <joint name="leg_2_joint1" type="revolute">
    <parent link="leg_2_body0"/>
    <child link="leg_2_body1"/>
    <origin xyz="0 0.12 0" rpy="0 0 0"/>
    <axis xyz="0 1 0"/>
    <limit lower="-0.79" upper="0.79" effort="10" velocity="1"/>
    <dynamics damping="0.7"/>
  </joint>

  <link name="leg_2_body2">
    <visual>
      <geometry>
        <box size="0.1 0.2 0.1"/>
      </geometry>
      <material name="leg_color"/>
    </visual>
    <collision>
      <geometry>
        <box size="0.1 0.2 0.1"/>
      </geometry>
    </collision>
    <inertial>
      <mass value="0.05"/>
      <inertia ixx="0.0001" ixy="0.0" ixz="0.0" iyy="0.0001" iyz="0.0" izz="0.0001"/>
    </inertial>
  </link>

  <joint name="leg_2_joint2" type="revolute">
    <parent link="leg_2_body1"/>
    <child link="leg_2_body2"/>
    <origin xyz="0 0.12 0" rpy="0 0 0"/>
    <axis xyz="1 0 0"/>
    <limit lower="0" upper="1.05" effort="10" velocity="1"/>
    <dynamics damping="0.7"/>
  </joint>

  <link name="leg_2_body3">
    <visual>
      <geometry>
        <box size="0.1 0.2 0.1"/>
      </geometry>
      <material name="leg_color"/>
    </visual>
    <collision>
      <geometry>
        <box size="0.1 0.2 0.1"/>
      </geometry>
    </collision>
    <inertial>
      <mass value="0.05"/>
      <inertia ixx="0.0001" ixy="0.0" ixz="0.0" iyy="0.0001" iyz="0.0" izz="0.0001"/>
    </inertial>
  </link>

  <joint name="leg_2_joint3" type="revolute">
    <parent link="leg_2_body2"/>
    <child link="leg_2_body3"/>
    <origin xyz="0 0.12 0" rpy="0 0 0"/>
    <axis xyz="1 0 0"/>
    <limit lower="0" upper="1.05" effort="10" velocity="1"/>
    <dynamics damping="0.7"/>
  </joint>

  <!-- Front Right Leg (leg 3) -->
  <link name="leg_3_body0">
    <visual>
      <geometry>
        <box size="0.1 0.2 0.1"/>
      </geometry>
      <material name="leg_color"/>
    </visual>
    <collision>
      <geometry>
        <box size="0.1 0.2 0.1"/>
      </geometry>
    </collision>
    <inertial>
      <mass value="0.05"/>
      <inertia ixx="0.0001" ixy="0.0" ixz="0.0" iyy="0.0001" iyz="0.0" izz="0.0001"/>
    </inertial>
  </link>

  <joint name="leg_3_joint0" type="fixed">
    <parent link="body"/>
    <child link="leg_3_body0"/>
    <origin xyz="0.45 -0.2 -0.1" rpy="0 0 3.14159"/>
  </joint>

  <link name="leg_3_body1">
    <visual>
      <geometry>
        <box size="0.1 0.2 0.1"/>
      </geometry>
      <material name="leg_color"/>
    </visual>
    <collision>
      <geometry>
        <box size="0.1 0.2 0.1"/>
      </geometry>
    </collision>
    <inertial>
      <mass value="0.05"/>
      <inertia ixx="0.0001" ixy="0.0" ixz="0.0" iyy="0.0001" iyz="0.0" izz="0.0001"/>
    </inertial>
  </link>

  <joint name="leg_3_joint1" type="revolute">
    <parent link="leg_3_body0"/>
    <child link="leg_3_body1"/>
    <origin xyz="0 0.12 0" rpy="0 0 0"/>
    <axis xyz="0 1 0"/>
    <limit lower="-0.79" upper="0.79" effort="10" velocity="1"/>
    <dynamics damping="0.7"/>
  </joint>

  <link name="leg_3_body2">
    <visual>
      <geometry>
        <box size="0.1 0.2 0.1"/>
      </geometry>
      <material name="leg_color"/>
    </visual>
    <collision>
      <geometry>
        <box size="0.1 0.2 0.1"/>
      </geometry>
    </collision>
    <inertial>
      <mass value="0.05"/>
      <inertia ixx="0.0001" ixy="0.0" ixz="0.0" iyy="0.0001" iyz="0.0" izz="0.0001"/>
    </inertial>
  </link>

  <joint name="leg_3_joint2" type="revolute">
    <parent link="leg_3_body1"/>
    <child link="leg_3_body2"/>
    <origin xyz="0 0.12 0" rpy="0 0 0"/>
    <axis xyz="1 0 0"/>
    <limit lower="0" upper="1.05" effort="10" velocity="1"/>
    <dynamics damping="0.7"/>
  </joint>

  <link name="leg_3_body3">
    <visual>
      <geometry>
        <box size="0.1 0.2 0.1"/>
      </geometry>
      <material name="leg_color"/>
    </visual>
    <collision>
      <geometry>
        <box size="0.1 0.2 0.1"/>
      </geometry>
    </collision>
    <inertial>
      <mass value="0.05"/>
      <inertia ixx="0.0001" ixy="0.0" ixz="0.0" iyy="0.0001" iyz="0.0" izz="0.0001"/>
    </inertial>
  </link>

  <joint name="leg_3_joint3" type="revolute">
    <parent link="leg_3_body2"/>
    <child link="leg_3_body3"/>
    <origin xyz="0 0.12 0" rpy="0 0 0"/>
    <axis xyz="1 0 0"/>
    <limit lower="0" upper="1.05" effort="10" velocity="1"/>
    <dynamics damping="0.7"/>
  </joint>

  <!-- Middle Right Leg (leg 4) -->
  <link name="leg_4_body0">
    <visual>
      <geometry>
        <box size="0.1 0.2 0.1"/>
      </geometry>
      <material name="leg_color"/>
    </visual>
    <collision>
      <geometry>
        <box size="0.1 0.2 0.1"/>
      </geometry>
    </collision>
    <inertial>
      <mass value="0.05"/>
      <inertia ixx="0.0001" ixy="0.0" ixz="0.0" iyy="0.0001" iyz="0.0" izz="0.0001"/>
    </inertial>
  </link>

  <joint name="leg_4_joint0" type="fixed">
    <parent link="body"/>
    <child link="leg_4_body0"/>
    <origin xyz="0 -0.2 -0.1" rpy="0 0 3.14159"/>
  </joint>

  <link name="leg_4_body1">
    <visual>
      <geometry>
        <box size="0.1 0.2 0.1"/>
      </geometry>
      <material name="leg_color"/>
    </visual>
    <collision>
      <geometry>
        <box size="0.1 0.2 0.1"/>
      </geometry>
    </collision>
    <inertial>
      <mass value="0.05"/>
      <inertia ixx="0.0001" ixy="0.0" ixz="0.0" iyy="0.0001" iyz="0.0" izz="0.0001"/>
    </inertial>
  </link>

  <joint name="leg_4_joint1" type="revolute">
    <parent link="leg_4_body0"/>
    <child link="leg_4_body1"/>
    <origin xyz="0 0.12 0" rpy="0 0 0"/>
    <axis xyz="0 1 0"/>
    <limit lower="-0.79" upper="0.79" effort="10" velocity="1"/>
    <dynamics damping="0.7"/>
  </joint>

  <link name="leg_4_body2">
    <visual>
      <geometry>
        <box size="0.1 0.2 0.1"/>
      </geometry>
      <material name="leg_color"/>
    </visual>
    <collision>
      <geometry>
        <box size="0.1 0.2 0.1"/>
      </geometry>
    </collision>
    <inertial>
      <mass value="0.05"/>
      <inertia ixx="0.0001" ixy="0.0" ixz="0.0" iyy="0.0001" iyz="0.0" izz="0.0001"/>
    </inertial>
  </link>

  <joint name="leg_4_joint2" type="revolute">
    <parent link="leg_4_body1"/>
    <child link="leg_4_body2"/>
    <origin xyz="0 0.12 0" rpy="0 0 0"/>
    <axis xyz="1 0 0"/>
    <limit lower="0" upper="1.05" effort="10" velocity="1"/>
    <dynamics damping="0.7"/>
  </joint>

  <link name="leg_4_body3">
    <visual>
      <geometry>
        <box size="0.1 0.2 0.1"/>
      </geometry>
      <material name="leg_color"/>
    </visual>
    <collision>
      <geometry>
        <box size="0.1 0.2 0.1"/>
      </geometry>
    </collision>
    <inertial>
      <mass value="0.05"/>
      <inertia ixx="0.0001" ixy="0.0" ixz="0.0" iyy="0.0001" iyz="0.0" izz="0.0001"/>
    </inertial>
  </link>

  <joint name="leg_4_joint3" type="revolute">
    <parent link="leg_4_body2"/>
    <child link="leg_4_body3"/>
    <origin xyz="0 0.12 0" rpy="0 0 0"/>
    <axis xyz="1 0 0"/>
    <limit lower="0" upper="1.05" effort="10" velocity="1"/>
    <dynamics damping="0.7"/>
  </joint>

  <!-- Rear Right Leg (leg 5) -->
  <link name="leg_5_body0">
    <visual>
      <geometry>
        <box size="0.1 0.2 0.1"/>
      </geometry>
      <material name="leg_color"/>
    </visual>
    <collision>
      <geometry>
        <box size="0.1 0.2 0.1"/>
      </geometry>
    </collision>
    <inertial>
      <mass value="0.05"/>
      <inertia ixx="0.0001" ixy="0.0" ixz="0.0" iyy="0.0001" iyz="0.0" izz="0.0001"/>
    </inertial>
  </link>

  <joint name="leg_5_joint0" type="fixed">
    <parent link="body"/>
    <child link="leg_5_body0"/>
    <origin xyz="-0.45 -0.2 -0.1" rpy="0 0 3.14159"/>
  </joint>

  <link name="leg_5_body1">
    <visual>
      <geometry>
        <box size="0.1 0.2 0.1"/>
      </geometry>
      <material name="leg_color"/>
    </visual>
    <collision>
      <geometry>
        <box size="0.1 0.2 0.1"/>
      </geometry>
    </collision>
    <inertial>
      <mass value="0.05"/>
      <inertia ixx="0.0001" ixy="0.0" ixz="0.0" iyy="0.0001" iyz="0.0" izz="0.0001"/>
    </inertial>
  </link>

  <joint name="leg_5_joint1" type="revolute">
    <parent link="leg_5_body0"/>
    <child link="leg_5_body1"/>
    <origin xyz="0 0.12 0" rpy="0 0 0"/>
    <axis xyz="0 1 0"/>
    <limit lower="-0.79" upper="0.79" effort="10" velocity="1"/>
    <dynamics damping="0.7"/>
  </joint>

  <link name="leg_5_body2">
    <visual>
      <geometry>
        <box size="0.1 0.2 0.1"/>
      </geometry>
      <material name="leg_color"/>
    </visual>
    <collision>
      <geometry>
        <box size="0.1 0.2 0.1"/>
      </geometry>
    </collision>
    <inertial>
      <mass value="0.05"/>
      <inertia ixx="0.0001" ixy="0.0" ixz="0.0" iyy="0.0001" iyz="0.0" izz="0.0001"/>
    </inertial>
  </link>

  <joint name="leg_5_joint2" type="revolute">
    <parent link="leg_5_body1"/>
    <child link="leg_5_body2"/>
    <origin xyz="0 0.12 0" rpy="0 0 0"/>
    <axis xyz="1 0 0"/>
    <limit lower="0" upper="1.05" effort="10" velocity="1"/>
    <dynamics damping="0.7"/>
  </joint>

  <link name="leg_5_body3">
    <visual>
      <geometry>
        <box size="0.1 0.2 0.1"/>
      </geometry>
      <material name="leg_color"/>
    </visual>
    <collision>
      <geometry>
        <box size="0.1 0.2 0.1"/>
      </geometry>
    </collision>
    <inertial>
      <mass value="0.05"/>
      <inertia ixx="0.0001" ixy="0.0" ixz="0.0" iyy="0.0001" iyz="0.0" izz="0.0001"/>
    </inertial>
  </link>

  <joint name="leg_5_joint3" type="revolute">
    <parent link="leg_5_body2"/>
    <child link="leg_5_body3"/>
    <origin xyz="0 0.12 0" rpy="0 0 0"/>
    <axis xyz="1 0 0"/>
    <limit lower="0" upper="1.05" effort="10" velocity="1"/>
    <dynamics damping="0.7"/>
  </joint>

</robot>